Workbook

Sheet 300總表
A1: 苗栗縣立永貞國民小學
A2: 總表[預算]
A3: 工程名稱 | B3: 115年度圖書館空間改善工程 | G3: 會計科目
A4: 施工地點 | B4: 苗栗縣 | G4: 工程編號
A5: 項次 | B5: 工程項目 | G5: 金額 | J5: 備註
A6: 壹 | B6: 發包工程費
A7: 一 | B7: 拆除清運工程 | G7: ='300詳細價目表 '!F14 -> 108200
A8: 二 | B8: 水電燈具工程 | G8: ='300詳細價目表 '!F40 -> 255010
A9: 三 | B9: 裝修工程 | G9: ='300詳細價目表 '!F69 -> 1681500
A10: 四 | B10: 家具及設備工程 | G10: ='300詳細價目表 '!F79 -> 264210
A11: 五 | B11: 假設工程 | G11: ='300詳細價目表 '!F86 -> 70000
B12: 合計A(一~五) | G12: ='300詳細價目表 '!F87 -> 2378920
A13: 六 | B13: 職業安全衛生管理費 | G13: ='300詳細價目表 '!F88 -> 16652.44
A14: 七 | B14: 工程品管作業費 | G14: ='300詳細價目表 '!F89 -> 166524.4
A15: 八 | B15: 包商利潤管理費 | G15: ='300詳細價目表 '!F90 -> 16652.44
A16: 九 | B16: 營造綜合保險費 | G16: ='300詳細價目表 '!F91 -> 8326.22
A17: 十 | B17: 包商營業稅 | G17: ='300詳細價目表 '!F92 -> 128937.46
A18: 貳 | B18: 自辦工程費
A19: 一 | B19: 工理管理費 | G19: ='300詳細價目表 '!F96 -> 71367.6
A20: 二 | B20: 空氣汙染防制費 | G20: ='300詳細價目表 '!F97 -> 8148.0389
A21: 三 | B21: 委外設計監造費 | G21: ='300詳細價目表 '!F98 -> 204471.12
B22: 小計 | G22: ='300詳細價目表 '!F99 -> 283986.76
B23: 總計 | G23: ='300詳細價目表 '!F100 -> 2999999.7
A24: 本 工 程 總 額 | C24: 新台幣 | D24: 參佰萬

Sheet 300詳細價目表 
A1: 苗栗縣永貞國小中學
A2: 詳細價目表[預算]
A3: 工程名稱 | B3: 115年度圖書館空間改善工程 | E3: 會計科目
A4: 施工地點 | B4: 苗栗縣 | E4: 工程編號
A5: 項 次 | B5: 項 目 及 說 明 | C5: 單 位 | D5: 數 量 | E5: 單 價 | F5: 複 價 | G5: 編碼(備註)
A6: 壹 | B6: 發包工程費
A7: 一 | B7: 拆除清運工程
A8: 1 | B8: 既有燈具、吊扇、拆除清運 | C8: 式 | D8: 1 | E8: 16000 | F8: =E8*D8 -> 16000
A9: 2 | B9: 既有捲簾含軌道五金拆卸 | C9: 式 | D9: 1 | E9: 8500 | F9: =E9*D9 -> 8500
A10: 3 | B10: 既有鐵窗及鐵捲門拆除(交由校方) | C10: 式 | D10: 1 | E10: 12500 | F10: =E10*D10 -> 12500
A11: 4 | B11: 既有水槽拆除清運 | C11: 座 | D11: 1 | E11: 16000 | F11: =E11*D11 -> 16000
A12: 5 | B12: 既有木櫃拆除清運 | C12: 座 | D12: 4 | E12: 6900 | F12: =E12*D12 -> 27600
A13: 6 | B13: 既有土台拆除清運 | C13: 座 | D13: 4 | E13: 6900 | F13: =E13*D13 -> 27600 | G13: 含地板修復
B14: 小計 | F14: =SUM(F8:F13) -> 108200
A15: 二 | B15: 水電燈具工程
A16: 1 | B16: 藤扁吊燈(大) | C16: 組 | D16: 1 | E16: 4800 | F16: =E16*D16 -> 4800
A17: 2 | B17: 藤扁吊燈(小) | C17: 組 | D17: 4 | E17: 2700 | F17: =E17*D17 -> 10800
A18: 3 | B18: 吊燈安裝工資 | C18: 組 | D18: 6 | E18: 1080 | F18: =E18*D18 -> 6480
A19: 4 | B19: 吸頂圓筒燈 | C19: 組 | D19: 32 | E19: 850 | F19: =E19*D19 -> 27200
A20: 5 | B20: 吸頂圓筒燈安裝工資 | C20: 組 | D20: 32 | E20: 450 | F20: =E20*D20 -> 14400
A21: 6 | B21: LED崁燈 | C21: 組 | D21: 9 | E21: 850 | F21: =E21*D21 -> 7650
A22: 7 | B22: LED崁燈安裝工資 | C22: 組 | D22: 9 | E22: 640 | F22: =E22*D22 -> 5760
A23: 8 | B23: 軌道含吊桿 | C23: 米 | D23: 6 | E23: 640 | F23: =E23*D23 -> 3840
A24: 9 | B24: 投射型軌道燈 | C24: 組 | D24: 3 | E24: 480 | F24: =E24*D24 -> 1440
A25: 10 | B25: 散光型軌道燈 | C25: 組 | D25: 3 | E25: 480 | F25: =E25*D25 -> 1440
A26: 11 | B26: 軌道燈安裝工資 | C26: 組 | D26: 6 | E26: 105 | F26: =E26*D26 -> 630
A27: 12 | B27: 新設線型吊燈 | C27: 組 | D27: 1 | E27: 3600 | F27: =E27*D27 -> 3600
... A32: 17 | B32: 新設雙連插座接地型 | C32: 迴 | D32: 6 | E32: 1595 | F32: =E32*D32 -> 9570
A33: 18 | B33: 新設雙連插座接地型-USB插座 | C33: 迴 | D33: 2 | E33: 2700 | F33: =E33*D33 -> 5400 | G33: 窗邊閱讀桌(W140*D60cm)各設1個USB插座
A34: 19 | B34: 新設網路插座接地型 | C34: 迴 | D34: 3 | E34: 1620 | F34: =E34*D34 -> 4860
A35: 20 | B35: 新設電視插座接地型 | C35: 迴 | D35: 1 | E35: 1620 | F35: =E35*D35 -> 1620
A36: 21 | B36: 新設電話插座接地型 | C36: 迴 | D36: 1 | E36: 1620 | F36: =E36*D36 -> 1620
A37: 22 | B37: 既有冷氣拆裝 | C37: 式 | D37: 1 | E37: 17000 | F37: =E37*D37 -> 17000
A38: 23 | B38: 既有開關迴路檢整佈線 | C38: 迴 | D38: 14 | E38: 5400 | F38: =E38*D38 -> 75600
A39: 24 | B39: 既有室內型攝影機拆裝(含線路安裝) | C39: 支 | D39: 2 | E39: 2500 | F39: =D39*E39 -> 5000 | G39: 由校方提供攝影機設備代為安裝
B40: 小計 | F40: =SUM(F16:F39) -> 255010
A41: 三 | B41: 裝修工程
A42: 1 | B42: 入口處-大門造型入口意象(含logo,主題書櫃) | C42: 式 | D42: 1 | E42: 256500 | F42: =E42*D42 -> 256500
A43: 2 | B43: 入口處-木作移動式還書箱 | C43: 座 | D43: 1 | E43: 9000 | F43: =E43*D43 -> 9000
A44: 3 | B44: 木作服務櫃台(含單面抽屜+線型燈條) | C44: 座 | D44: 1 | E44: 105000 | F44: =E44*D44 -> 105000
...

Sheet 單價分析表
A1: 苗栗縣立三灣國民中學
A2: 單價分析表[預算]
A3: 工程名稱:苗栗縣立三灣國民中學教師宿舍修繕工程
A4: 項次： | B4: 工程編號：
A5: 壹.二.1 | B5: 櫃檯區造型矮牆 | G5: 單位: | H5: 尺 | J5: 編碼(備註)
B6: 工料名稱 | F6: 單位 | G6: 數量 | H6: 單價 | I6: 複價
B7: 角材 | F7: 支 | G7: 8 | H7: 500 | I7: =H7*G7 -> 4000 | K7: 30800
B8: 皮板 | F8: 片 | G8: 10 | H8: 1200 | I8: =H8*G8 -> 12000
B9: 五金配件 | F9: 式 | G9: 1 | H9: 1500 | I9: =H9*G9 -> 1500
B10: 安裝工資 | F10: 工 | G10: 3 | H10: 3500 | I10: =H10*G10 -> 10500
B11: 搬運及備料 | F11: 式 | G11: 1 | H11: 2800 | I11: =H11*G11 -> 2800
B12: 小計 | F12: =SUM(I7:I11) -> 30800
A22: 壹.二.3 | B22: 柱面修飾 | G22: 單位: | H22: 處
B23: 工料名稱 | F23: 單位 | G23: 數量 | H23: 單價 | I23: 複價 | K23: 28000
B24: 角材 | F24: 支 | G24: 6 | H24: 500 | I24: =H24*G24 -> 3000
B25: 皮板 | F25: 片 | G25: 8 | H25: 1200 | I25: =H25*G25 -> 9600
B26: 五金配件 | F26: 式 | G26: 1 | H26: 2000 | I26: =H26*G26 -> 2000
B27: 安裝工資 | F27: 工 | G27: 3 | H27: 3500 | I27: =H27*G27 -> 10500
B28: 搬運及備料 | F28: 式 | G28: 1 | H28: 2900 | I28: =H28*G28 -> 2900
B29: 小計 | F29: =SUM(I24:I28) -> 28000
A39: 壹.二.10 | B39: =#REF! -> #REF! | G39: 單位: | H39: =#REF! -> #REF! | J39: 編碼(備註)
B40: 工料名稱 | F40: 單位 | G40: 數量 | H40: 單價 | I40: 複價 | K40: =#REF! -> #REF!
B41: 角材 | F41: 支 | G41: 0.4 | H41: 500 | I41: =H41*G41 -> 200
B42: 皮板 | F42: 片 | G42: 0.5 | H42: 1200 | I42: =H42*G42 -> 600
B43: 五金配件 | F43: 式 | G43: 1 | H43: 80 | I43: =H43*G43 -> 80
B44: 安裝工資 | F44: 工 | G44: 1 | H44: 300 | I44: =H44*G44 -> 300
B45: 搬運及備料 | F45: 式 | G45: 1 | H45: 500 | I45: =H45*G45 -> 500
B46: 小計 | F46: =SUM(I41:I45) -> 1680
A56: 壹.二.17 | B56: =#REF! -> #REF! | G56: 單位: | H56: =#REF! -> #REF!
B57: 工料名稱 | F57: 單位 | G57: 數量 | H57: 單價 | I57: 複價
B58: 牆面批土 | F58: 坪 | G58: 1 | H58: 150 | I58: =H58*G58 -> 150 | K58: =#REF! -> #REF!
B59: 水泥漆 | F59: 坪 | G59: 1 | H59: 200 | I59: =H59*G59 -> 200
B60: 五金、耗材配件 | F60: 式 | G60: 1 | H60: 33 | I60: =H60*G60 -> 33
B61: 施作工資 | F61: 工 | G61: 1 | H61: 500 | I61: =H61*G61 -> 500
B62: 備料 | F62: 式 | G62: 1 | H62: 43 | I62: =H62*G62 -> 43
B63: 小計 | F63: =SUM(I58:I62) -> 926
A74: 參-19 | B74: =#REF! -> #REF! | G74: 單位: | H74: =#REF! -> #REF! | J74: 編碼(備註)
B75: 工料名稱 | F75: 單位 | G75: 數量 | H75: 單價 | I75: 複價
B76: PVC地磚 | F76: 坪 | G76: 1 | H76: 750 | I76: =H76*G76 -> 750 | K76: =#REF! -> #REF!
B77: 地板感壓膠 | F77: 坪 | G77: 1 | H77: 250 | I77: =H77*G77 -> 250
...
